{"trial_id": "11", "hyperparameters": {"space": [{"class_name": "Int", "config": {"name": "conv_0", "default": 16, "conditions": [], "min_value": 8, "max_value": 64, "step": 8, "sampling": "linear"}}, {"class_name": "Float", "config": {"name": "dropout_0", "default": 0.5, "conditions": [], "min_value": 0.1, "max_value": 0.8, "step": 0.1, "sampling": "linear"}}, {"class_name": "Int", "config": {"name": "conv_1", "default": 32, "conditions": [], "min_value": 16, "max_value": 128, "step": 8, "sampling": "linear"}}, {"class_name": "Float", "config": {"name": "dropout_1", "default": 0.5, "conditions": [], "min_value": 0.1, "max_value": 0.8, "step": 0.1, "sampling": "linear"}}, {"class_name": "Int", "config": {"name": "dense_0", "default": 128, "conditions": [], "min_value": 32, "max_value": 256, "step": 8, "sampling": "linear"}}, {"class_name": "Float", "config": {"name": "dropout_2", "default": 0.5, "conditions": [], "min_value": 0.1, "max_value": 0.8, "step": 0.1, "sampling": "linear"}}, {"class_name": "Int", "config": {"name": "dense_1", "default": 64, "conditions": [], "min_value": 16, "max_value": 128, "step": 8, "sampling": "linear"}}, {"class_name": "Float", "config": {"name": "dropout_3", "default": 0.5, "conditions": [], "min_value": 0.1, "max_value": 0.8, "step": 0.1, "sampling": "linear"}}, {"class_name": "Float", "config": {"name": "learning_rate", "default": 0.001, "conditions": [], "min_value": 1e-05, "max_value": 0.001, "step": null, "sampling": "log"}}], "values": {"conv_0": 32, "dropout_0": 0.1, "conv_1": 120, "dropout_1": 0.4, "dense_0": 216, "dropout_2": 0.7000000000000001, "dense_1": 24, "dropout_3": 0.4, "learning_rate": 0.0004737761473125343}}, "metrics": {"metrics": {}}, "score": null, "best_step": 0, "status": "FAILED", "message": "Traceback (most recent call last):\n  File \"/home/luiz/.local/lib/python3.10/site-packages/keras_tuner/src/engine/base_tuner.py\", line 274, in _try_run_and_update_trial\n    self._run_and_update_trial(trial, *fit_args, **fit_kwargs)\n  File \"/home/luiz/.local/lib/python3.10/site-packages/keras_tuner/src/engine/base_tuner.py\", line 239, in _run_and_update_trial\n    results = self.run_trial(trial, *fit_args, **fit_kwargs)\n  File \"/home/luiz/.local/lib/python3.10/site-packages/keras_tuner/src/engine/tuner.py\", line 314, in run_trial\n    obj_value = self._build_and_fit_model(trial, *args, **copied_kwargs)\n  File \"/home/luiz/.local/lib/python3.10/site-packages/keras_tuner/src/engine/tuner.py\", line 233, in _build_and_fit_model\n    results = self.hypermodel.fit(hp, model, *args, **kwargs)\n  File \"/home/luiz/.local/lib/python3.10/site-packages/keras_tuner/src/engine/hypermodel.py\", line 149, in fit\n    return model.fit(*args, **kwargs)\n  File \"/home/luiz/.local/lib/python3.10/site-packages/keras/src/utils/traceback_utils.py\", line 122, in error_handler\n    raise e.with_traceback(filtered_tb) from None\n  File \"/home/luiz/.local/lib/python3.10/site-packages/tensorflow/python/eager/execute.py\", line 53, in quick_execute\n    tensors = pywrap_tfe.TFE_Py_Execute(ctx._handle, device_name, op_name,\ntensorflow.python.framework.errors_impl.ResourceExhaustedError: Graph execution error:\n\nDetected at node StatefulPartitionedCall defined at (most recent call last):\n  File \"/usr/lib/python3.10/runpy.py\", line 196, in _run_module_as_main\n\n  File \"/usr/lib/python3.10/runpy.py\", line 86, in _run_code\n\n  File \"/home/luiz/.local/lib/python3.10/site-packages/ipykernel_launcher.py\", line 18, in <module>\n\n  File \"/home/luiz/.local/lib/python3.10/site-packages/traitlets/config/application.py\", line 1075, in launch_instance\n\n  File \"/home/luiz/.local/lib/python3.10/site-packages/ipykernel/kernelapp.py\", line 739, in start\n\n  File \"/home/luiz/.local/lib/python3.10/site-packages/tornado/platform/asyncio.py\", line 205, in start\n\n  File \"/usr/lib/python3.10/asyncio/base_events.py\", line 603, in run_forever\n\n  File \"/usr/lib/python3.10/asyncio/base_events.py\", line 1909, in _run_once\n\n  File \"/usr/lib/python3.10/asyncio/events.py\", line 80, in _run\n\n  File \"/home/luiz/.local/lib/python3.10/site-packages/ipykernel/kernelbase.py\", line 545, in dispatch_queue\n\n  File \"/home/luiz/.local/lib/python3.10/site-packages/ipykernel/kernelbase.py\", line 534, in process_one\n\n  File \"/home/luiz/.local/lib/python3.10/site-packages/ipykernel/kernelbase.py\", line 437, in dispatch_shell\n\n  File \"/home/luiz/.local/lib/python3.10/site-packages/ipykernel/ipkernel.py\", line 362, in execute_request\n\n  File \"/home/luiz/.local/lib/python3.10/site-packages/ipykernel/kernelbase.py\", line 778, in execute_request\n\n  File \"/home/luiz/.local/lib/python3.10/site-packages/ipykernel/ipkernel.py\", line 449, in do_execute\n\n  File \"/home/luiz/.local/lib/python3.10/site-packages/ipykernel/zmqshell.py\", line 549, in run_cell\n\n  File \"/home/luiz/.local/lib/python3.10/site-packages/IPython/core/interactiveshell.py\", line 3075, in run_cell\n\n  File \"/home/luiz/.local/lib/python3.10/site-packages/IPython/core/interactiveshell.py\", line 3130, in _run_cell\n\n  File \"/home/luiz/.local/lib/python3.10/site-packages/IPython/core/async_helpers.py\", line 128, in _pseudo_sync_runner\n\n  File \"/home/luiz/.local/lib/python3.10/site-packages/IPython/core/interactiveshell.py\", line 3334, in run_cell_async\n\n  File \"/home/luiz/.local/lib/python3.10/site-packages/IPython/core/interactiveshell.py\", line 3517, in run_ast_nodes\n\n  File \"/home/luiz/.local/lib/python3.10/site-packages/IPython/core/interactiveshell.py\", line 3577, in run_code\n\n  File \"/tmp/ipykernel_1434/144721382.py\", line 2, in <module>\n\n  File \"/mnt/c/Users/luiza/Desktop/Mestrado/Trabalho/Trainer/Trainer.py\", line 30, in train\n\n  File \"/home/luiz/.local/lib/python3.10/site-packages/keras_tuner/src/engine/base_tuner.py\", line 234, in search\n\n  File \"/home/luiz/.local/lib/python3.10/site-packages/keras_tuner/src/engine/base_tuner.py\", line 274, in _try_run_and_update_trial\n\n  File \"/home/luiz/.local/lib/python3.10/site-packages/keras_tuner/src/engine/base_tuner.py\", line 239, in _run_and_update_trial\n\n  File \"/home/luiz/.local/lib/python3.10/site-packages/keras_tuner/src/engine/tuner.py\", line 314, in run_trial\n\n  File \"/home/luiz/.local/lib/python3.10/site-packages/keras_tuner/src/engine/tuner.py\", line 233, in _build_and_fit_model\n\n  File \"/home/luiz/.local/lib/python3.10/site-packages/keras_tuner/src/engine/hypermodel.py\", line 149, in fit\n\n  File \"/home/luiz/.local/lib/python3.10/site-packages/keras/src/utils/traceback_utils.py\", line 117, in error_handler\n\n  File \"/home/luiz/.local/lib/python3.10/site-packages/keras/src/backend/tensorflow/trainer.py\", line 343, in fit\n\n  File \"/home/luiz/.local/lib/python3.10/site-packages/keras/src/utils/traceback_utils.py\", line 117, in error_handler\n\n  File \"/home/luiz/.local/lib/python3.10/site-packages/keras/src/backend/tensorflow/trainer.py\", line 429, in evaluate\n\n  File \"/home/luiz/.local/lib/python3.10/site-packages/keras/src/backend/tensorflow/trainer.py\", line 165, in one_step_on_iterator\n\nOut of memory while trying to allocate 16797952 bytes.\n\t [[{{node StatefulPartitionedCall}}]]\nHint: If you want to see a list of allocated tensors when OOM happens, add report_tensor_allocations_upon_oom to RunOptions for current allocation info. This isn't available when running in Eager mode.\n [Op:__inference_one_step_on_iterator_816991]\n"}